Internal Server Error: /dashboard/
Traceback (most recent call last):
  File "C:\Python313\Lib\site-packages\django\core\handlers\exception.py", line 55, in inner
    response = get_response(request)
  File "C:\Python313\Lib\site-packages\django\core\handlers\base.py", line 197, in _get_response
    response = wrapped_callback(request, *callback_args, **callback_kwargs)
  File "C:\Python313\Lib\site-packages\django\contrib\auth\decorators.py", line 60, in _view_wrapper
    return view_func(request, *args, **kwargs)
  File "C:\Users\ratan\OneDrive\Desktop\PrintEase\SmartDocX\users\views.py", line 236, in dashboard
    orders_table = get_owner_orders_table(owner_unique_url)
                   ^^^^^^^^^^^^^^^^^^^^^^
NameError: name 'get_owner_orders_table' is not defined
"GET /dashboard/ HTTP/1.1" 500 145
Internal Server Error: /dashboard/
Traceback (most recent call last):
  File "C:\Python313\Lib\site-packages\django\core\handlers\exception.py", line 55, in inner
    response = get_response(request)
  File "C:\Python313\Lib\site-packages\django\core\handlers\base.py", line 197, in _get_response
    response = wrapped_callback(request, *callback_args, **callback_kwargs)
  File "C:\Python313\Lib\site-packages\django\contrib\auth\decorators.py", line 60, in _view_wrapper
    return view_func(request, *args, **kwargs)
  File "C:\Users\ratan\OneDrive\Desktop\PrintEase\SmartDocX\users\views.py", line 236, in dashboard
    orders_table = get_owner_orders_table(owner_unique_url)
                   ^^^^^^^^^^^^^^^^^^^^^^
NameError: name 'get_owner_orders_table' is not defined
"GET /dashboard/ HTTP/1.1" 500 145
Internal Server Error: /dashboard/
Traceback (most recent call last):
  File "C:\Python313\Lib\site-packages\django\core\handlers\exception.py", line 55, in inner
    response = get_response(request)
  File "C:\Python313\Lib\site-packages\django\core\handlers\base.py", line 197, in _get_response
    response = wrapped_callback(request, *callback_args, **callback_kwargs)
  File "C:\Python313\Lib\site-packages\django\contrib\auth\decorators.py", line 60, in _view_wrapper
    return view_func(request, *args, **kwargs)
  File "C:\Users\ratan\OneDrive\Desktop\PrintEase\SmartDocX\users\views.py", line 236, in dashboard
    orders_table = get_owner_orders_table(owner_unique_url)
                   ^^^^^^^^^^^^^^^^^^^^^^
NameError: name 'get_owner_orders_table' is not defined
"GET /dashboard/ HTTP/1.1" 500 145
Internal Server Error: /dashboard/
Traceback (most recent call last):
  File "C:\Python313\Lib\site-packages\django\core\handlers\exception.py", line 55, in inner
    response = get_response(request)
  File "C:\Python313\Lib\site-packages\django\core\handlers\base.py", line 197, in _get_response
    response = wrapped_callback(request, *callback_args, **callback_kwargs)
  File "C:\Python313\Lib\site-packages\django\contrib\auth\decorators.py", line 60, in _view_wrapper
    return view_func(request, *args, **kwargs)
  File "C:\Users\ratan\OneDrive\Desktop\PrintEase\SmartDocX\users\views.py", line 236, in dashboard
    orders_table = get_owner_orders_table(owner_unique_url)
                   ^^^^^^^^^^^^^^^^^^^^^^
NameError: name 'get_owner_orders_table' is not defined
"GET /dashboard/ HTTP/1.1" 500 145
Internal Server Error: /dashboard/
Traceback (most recent call last):
  File "C:\Python313\Lib\site-packages\django\core\handlers\exception.py", line 55, in inner
    response = get_response(request)
  File "C:\Python313\Lib\site-packages\django\core\handlers\base.py", line 197, in _get_response
    response = wrapped_callback(request, *callback_args, **callback_kwargs)
  File "C:\Python313\Lib\site-packages\django\contrib\auth\decorators.py", line 60, in _view_wrapper
    return view_func(request, *args, **kwargs)
  File "C:\Users\ratan\OneDrive\Desktop\PrintEase\SmartDocX\users\views.py", line 350, in dashboard
    orders_and_revenue.to_json("orders_and_revenue.json", orient="records")
    ^^^^^^^^^^^^^^^^^^^^^^^^^^
AttributeError: 'dict' object has no attribute 'to_json'
"GET /dashboard/ HTTP/1.1" 500 82900
Internal Server Error: /dashboard/
Traceback (most recent call last):
  File "C:\Python313\Lib\site-packages\django\core\handlers\exception.py", line 55, in inner
    response = get_response(request)
  File "C:\Python313\Lib\site-packages\django\core\handlers\base.py", line 197, in _get_response
    response = wrapped_callback(request, *callback_args, **callback_kwargs)
  File "C:\Python313\Lib\site-packages\django\contrib\auth\decorators.py", line 60, in _view_wrapper
    return view_func(request, *args, **kwargs)
  File "C:\Users\ratan\OneDrive\Desktop\PrintEase\SmartDocX\users\views.py", line 368, in dashboard
    for order in orders_table:
                 ^^^^^^^^^^^^
NameError: name 'orders_table' is not defined. Did you mean: 'order_table'?
"GET /dashboard/ HTTP/1.1" 500 80075
Internal Server Error: /dashboard/
Traceback (most recent call last):
  File "C:\Python313\Lib\site-packages\django\core\handlers\exception.py", line 55, in inner
    response = get_response(request)
  File "C:\Python313\Lib\site-packages\django\core\handlers\base.py", line 197, in _get_response
    response = wrapped_callback(request, *callback_args, **callback_kwargs)
  File "C:\Python313\Lib\site-packages\django\contrib\auth\decorators.py", line 60, in _view_wrapper
    return view_func(request, *args, **kwargs)
  File "C:\Users\ratan\OneDrive\Desktop\PrintEase\SmartDocX\users\views.py", line 368, in dashboard
    for order in orders_table:
                 ^^^^^^^^^^^^
NameError: name 'orders_table' is not defined. Did you mean: 'order_table'?
"GET /dashboard/ HTTP/1.1" 500 80075
Internal Server Error: /dashboard/
Traceback (most recent call last):
  File "C:\Python313\Lib\site-packages\django\core\handlers\exception.py", line 55, in inner
    response = get_response(request)
  File "C:\Python313\Lib\site-packages\django\core\handlers\base.py", line 197, in _get_response
    response = wrapped_callback(request, *callback_args, **callback_kwargs)
  File "C:\Python313\Lib\site-packages\django\contrib\auth\decorators.py", line 60, in _view_wrapper
    return view_func(request, *args, **kwargs)
  File "C:\Users\ratan\OneDrive\Desktop\PrintEase\SmartDocX\users\views.py", line 368, in dashboard
    for order in orders_table:
                 ^^^^^^^^^^^^
NameError: name 'orders_table' is not defined. Did you mean: 'order_table'?
"GET /dashboard/ HTTP/1.1" 500 80075
Internal Server Error: /dashboard/
Traceback (most recent call last):
  File "C:\Python313\Lib\site-packages\django\core\handlers\exception.py", line 55, in inner
    response = get_response(request)
  File "C:\Python313\Lib\site-packages\django\core\handlers\base.py", line 197, in _get_response
    response = wrapped_callback(request, *callback_args, **callback_kwargs)
  File "C:\Python313\Lib\site-packages\django\contrib\auth\decorators.py", line 60, in _view_wrapper
    return view_func(request, *args, **kwargs)
  File "C:\Users\ratan\OneDrive\Desktop\PrintEase\SmartDocX\users\views.py", line 368, in dashboard
    for order in orders_table:
                 ^^^^^^^^^^^^
NameError: name 'orders_table' is not defined. Did you mean: 'order_table'?
"GET /dashboard/ HTTP/1.1" 500 80075
Internal Server Error: /dashboard/
Traceback (most recent call last):
  File "C:\Python313\Lib\site-packages\django\core\handlers\exception.py", line 55, in inner
    response = get_response(request)
  File "C:\Python313\Lib\site-packages\django\core\handlers\base.py", line 197, in _get_response
    response = wrapped_callback(request, *callback_args, **callback_kwargs)
  File "C:\Python313\Lib\site-packages\django\contrib\auth\decorators.py", line 60, in _view_wrapper
    return view_func(request, *args, **kwargs)
  File "C:\Users\ratan\OneDrive\Desktop\PrintEase\SmartDocX\users\views.py", line 368, in dashboard
    for order in orders_table:
                 ^^^^^^^^^^^^
NameError: name 'orders_table' is not defined. Did you mean: 'order_table'?
"GET /dashboard/ HTTP/1.1" 500 80075
Internal Server Error: /dashboard/
Traceback (most recent call last):
  File "C:\Python313\Lib\site-packages\django\core\handlers\exception.py", line 55, in inner
    response = get_response(request)
  File "C:\Python313\Lib\site-packages\django\core\handlers\base.py", line 197, in _get_response
    response = wrapped_callback(request, *callback_args, **callback_kwargs)
  File "C:\Python313\Lib\site-packages\django\contrib\auth\decorators.py", line 60, in _view_wrapper
    return view_func(request, *args, **kwargs)
  File "C:\Users\ratan\OneDrive\Desktop\PrintEase\SmartDocX\users\views.py", line 368, in dashboard
    for order in orders_table:
                 ^^^^^^^^^^^^
NameError: name 'orders_table' is not defined. Did you mean: 'order_table'?
"GET /dashboard/ HTTP/1.1" 500 80075
Internal Server Error: /dashboard/
Traceback (most recent call last):
  File "C:\Python313\Lib\site-packages\django\core\handlers\exception.py", line 55, in inner
    response = get_response(request)
  File "C:\Python313\Lib\site-packages\django\core\handlers\base.py", line 197, in _get_response
    response = wrapped_callback(request, *callback_args, **callback_kwargs)
  File "C:\Python313\Lib\site-packages\django\contrib\auth\decorators.py", line 60, in _view_wrapper
    return view_func(request, *args, **kwargs)
  File "C:\Users\ratan\OneDrive\Desktop\PrintEase\SmartDocX\users\views.py", line 368, in dashboard
    for order in orders_table:
                 ^^^^^^^^^^^^
NameError: name 'orders_table' is not defined. Did you mean: 'order_table'?
"GET /dashboard/ HTTP/1.1" 500 80075
Internal Server Error: /dashboard/
Traceback (most recent call last):
  File "C:\Python313\Lib\site-packages\django\core\handlers\exception.py", line 55, in inner
    response = get_response(request)
  File "C:\Python313\Lib\site-packages\django\core\handlers\base.py", line 197, in _get_response
    response = wrapped_callback(request, *callback_args, **callback_kwargs)
  File "C:\Python313\Lib\site-packages\django\contrib\auth\decorators.py", line 60, in _view_wrapper
    return view_func(request, *args, **kwargs)
  File "C:\Users\ratan\OneDrive\Desktop\PrintEase\SmartDocX\users\views.py", line 368, in dashboard
    for order in orders_table:
                 ^^^^^^^^^^^^
NameError: name 'orders_table' is not defined. Did you mean: 'order_table'?
"GET /dashboard/ HTTP/1.1" 500 80075
Internal Server Error: /dashboard/
Traceback (most recent call last):
  File "C:\Python313\Lib\site-packages\django\core\handlers\exception.py", line 55, in inner
    response = get_response(request)
  File "C:\Python313\Lib\site-packages\django\core\handlers\base.py", line 197, in _get_response
    response = wrapped_callback(request, *callback_args, **callback_kwargs)
  File "C:\Python313\Lib\site-packages\django\contrib\auth\decorators.py", line 60, in _view_wrapper
    return view_func(request, *args, **kwargs)
  File "C:\Users\ratan\OneDrive\Desktop\PrintEase\SmartDocX\users\views.py", line 368, in dashboard
    for order in orders_table:
                 ^^^^^^^^^^^^
NameError: name 'orders_table' is not defined. Did you mean: 'order_table'?
"GET /dashboard/ HTTP/1.1" 500 80075
Internal Server Error: /dashboard/
Traceback (most recent call last):
  File "C:\Python313\Lib\site-packages\django\core\handlers\exception.py", line 55, in inner
    response = get_response(request)
  File "C:\Python313\Lib\site-packages\django\core\handlers\base.py", line 197, in _get_response
    response = wrapped_callback(request, *callback_args, **callback_kwargs)
  File "C:\Python313\Lib\site-packages\django\contrib\auth\decorators.py", line 60, in _view_wrapper
    return view_func(request, *args, **kwargs)
  File "C:\Users\ratan\OneDrive\Desktop\PrintEase\SmartDocX\users\views.py", line 368, in dashboard
    for order in orders_table:
                 ^^^^^^^^^^^^
NameError: name 'orders_table' is not defined. Did you mean: 'order_table'?
"GET /dashboard/ HTTP/1.1" 500 80075
Internal Server Error: /dashboard/
Traceback (most recent call last):
  File "C:\Python313\Lib\site-packages\django\core\handlers\exception.py", line 55, in inner
    response = get_response(request)
  File "C:\Python313\Lib\site-packages\django\core\handlers\base.py", line 197, in _get_response
    response = wrapped_callback(request, *callback_args, **callback_kwargs)
  File "C:\Python313\Lib\site-packages\django\contrib\auth\decorators.py", line 60, in _view_wrapper
    return view_func(request, *args, **kwargs)
  File "C:\Users\ratan\OneDrive\Desktop\PrintEase\SmartDocX\users\views.py", line 368, in dashboard
    for order in orders_table:
                 ^^^^^^^^^^^^
NameError: name 'orders_table' is not defined. Did you mean: 'order_table'?
"GET /dashboard/ HTTP/1.1" 500 80075
Internal Server Error: /dashboard/
Traceback (most recent call last):
  File "C:\Python313\Lib\site-packages\django\core\handlers\exception.py", line 55, in inner
    response = get_response(request)
  File "C:\Python313\Lib\site-packages\django\core\handlers\base.py", line 197, in _get_response
    response = wrapped_callback(request, *callback_args, **callback_kwargs)
  File "C:\Python313\Lib\site-packages\django\contrib\auth\decorators.py", line 60, in _view_wrapper
    return view_func(request, *args, **kwargs)
  File "C:\Users\ratan\OneDrive\Desktop\PrintEase\SmartDocX\users\views.py", line 368, in dashboard
    for order in orders_table:
                 ^^^^^^^^^^^^
NameError: name 'orders_table' is not defined. Did you mean: 'order_table'?
"GET /dashboard/ HTTP/1.1" 500 80075
Internal Server Error: /dashboard/
Traceback (most recent call last):
  File "C:\Python313\Lib\site-packages\django\core\handlers\exception.py", line 55, in inner
    response = get_response(request)
  File "C:\Python313\Lib\site-packages\django\core\handlers\base.py", line 197, in _get_response
    response = wrapped_callback(request, *callback_args, **callback_kwargs)
  File "C:\Python313\Lib\site-packages\django\contrib\auth\decorators.py", line 60, in _view_wrapper
    return view_func(request, *args, **kwargs)
  File "C:\Users\ratan\OneDrive\Desktop\PrintEase\SmartDocX\users\views.py", line 368, in dashboard
    for order in orders_table:
                 ^^^^^^^^^^^^
NameError: name 'orders_table' is not defined. Did you mean: 'order_table'?
"GET /dashboard/ HTTP/1.1" 500 80075
Internal Server Error: /dashboard/
Traceback (most recent call last):
  File "C:\Python313\Lib\site-packages\django\core\handlers\exception.py", line 55, in inner
    response = get_response(request)
  File "C:\Python313\Lib\site-packages\django\core\handlers\base.py", line 197, in _get_response
    response = wrapped_callback(request, *callback_args, **callback_kwargs)
  File "C:\Python313\Lib\site-packages\django\contrib\auth\decorators.py", line 60, in _view_wrapper
    return view_func(request, *args, **kwargs)
  File "C:\Users\ratan\OneDrive\Desktop\PrintEase\SmartDocX\users\views.py", line 368, in dashboard
    for order in orders_table:
                 ^^^^^^^^^^^^
NameError: name 'orders_table' is not defined. Did you mean: 'order_table'?
"GET /dashboard/ HTTP/1.1" 500 80075
Internal Server Error: /dashboard/
Traceback (most recent call last):
  File "C:\Python313\Lib\site-packages\django\core\handlers\exception.py", line 55, in inner
    response = get_response(request)
  File "C:\Python313\Lib\site-packages\django\core\handlers\base.py", line 197, in _get_response
    response = wrapped_callback(request, *callback_args, **callback_kwargs)
  File "C:\Python313\Lib\site-packages\django\contrib\auth\decorators.py", line 60, in _view_wrapper
    return view_func(request, *args, **kwargs)
  File "C:\Users\ratan\OneDrive\Desktop\PrintEase\SmartDocX\users\views.py", line 368, in dashboard
    for order in orders_table:
                 ^^^^^^^^^^^^
NameError: name 'orders_table' is not defined. Did you mean: 'order_table'?
"GET /dashboard/ HTTP/1.1" 500 80075
Internal Server Error: /dashboard/
Traceback (most recent call last):
  File "C:\Python313\Lib\site-packages\django\core\handlers\exception.py", line 55, in inner
    response = get_response(request)
  File "C:\Python313\Lib\site-packages\django\core\handlers\base.py", line 197, in _get_response
    response = wrapped_callback(request, *callback_args, **callback_kwargs)
  File "C:\Python313\Lib\site-packages\django\contrib\auth\decorators.py", line 60, in _view_wrapper
    return view_func(request, *args, **kwargs)
  File "C:\Users\ratan\OneDrive\Desktop\PrintEase\SmartDocX\users\views.py", line 368, in dashboard
    for order in orders_table:
                 ^^^^^^^^^^^^
NameError: name 'orders_table' is not defined. Did you mean: 'order_table'?
"GET /dashboard/ HTTP/1.1" 500 80075
Internal Server Error: /print_order/
Traceback (most recent call last):
  File "C:\Python313\Lib\site-packages\django\core\handlers\exception.py", line 55, in inner
    response = get_response(request)
  File "C:\Python313\Lib\site-packages\django\core\handlers\base.py", line 197, in _get_response
    response = wrapped_callback(request, *callback_args, **callback_kwargs)
  File "C:\Python313\Lib\site-packages\django\views\decorators\csrf.py", line 65, in _view_wrapper
    return view_func(request, *args, **kwargs)
  File "C:\Users\ratan\OneDrive\Desktop\PrintEase\SmartDocX\users\views.py", line 499, in print_order
    file_path = os.path.join(settings.MEDIA_ROOT, order.document)  # Construct full file path
  File "<frozen ntpath>", line 139, in join
  File "<frozen genericpath>", line 188, in _check_arg_types
TypeError: join() argument must be str, bytes, or os.PathLike object, not 'FieldFile'
"POST /print_order/ HTTP/1.1" 500 79654
Internal Server Error: /print_order/
Traceback (most recent call last):
  File "C:\Python313\Lib\site-packages\django\core\handlers\exception.py", line 55, in inner
    response = get_response(request)
  File "C:\Python313\Lib\site-packages\django\core\handlers\base.py", line 197, in _get_response
    response = wrapped_callback(request, *callback_args, **callback_kwargs)
  File "C:\Python313\Lib\site-packages\django\views\decorators\csrf.py", line 65, in _view_wrapper
    return view_func(request, *args, **kwargs)
  File "C:\Users\ratan\OneDrive\Desktop\PrintEase\SmartDocX\users\views.py", line 499, in print_order
    file_path = os.path.join(settings.MEDIA_ROOT, order.document)  # Construct full file path
  File "<frozen ntpath>", line 139, in join
  File "<frozen genericpath>", line 188, in _check_arg_types
TypeError: join() argument must be str, bytes, or os.PathLike object, not 'FieldFile'
"POST /print_order/ HTTP/1.1" 500 79648
Internal Server Error: /print_order/
Traceback (most recent call last):
  File "C:\Python313\Lib\site-packages\django\core\handlers\exception.py", line 55, in inner
    response = get_response(request)
  File "C:\Python313\Lib\site-packages\django\core\handlers\base.py", line 197, in _get_response
    response = wrapped_callback(request, *callback_args, **callback_kwargs)
  File "C:\Python313\Lib\site-packages\django\views\decorators\csrf.py", line 65, in _view_wrapper
    return view_func(request, *args, **kwargs)
  File "C:\Users\ratan\OneDrive\Desktop\PrintEase\SmartDocX\users\views.py", line 499, in print_order
    file_path = os.path.join(settings.MEDIA_ROOT, order.document)  # Construct full file path
  File "<frozen ntpath>", line 139, in join
  File "<frozen genericpath>", line 188, in _check_arg_types
TypeError: join() argument must be str, bytes, or os.PathLike object, not 'FieldFile'
"POST /print_order/ HTTP/1.1" 500 79654
Internal Server Error: /print_order/
Traceback (most recent call last):
  File "C:\Python313\Lib\site-packages\django\core\handlers\exception.py", line 55, in inner
    response = get_response(request)
  File "C:\Python313\Lib\site-packages\django\core\handlers\base.py", line 197, in _get_response
    response = wrapped_callback(request, *callback_args, **callback_kwargs)
  File "C:\Python313\Lib\site-packages\django\views\decorators\csrf.py", line 65, in _view_wrapper
    return view_func(request, *args, **kwargs)
  File "C:\Users\ratan\OneDrive\Desktop\PrintEase\SmartDocX\users\views.py", line 499, in print_order
    file_path = os.path.join(settings.MEDIA_ROOT, order.document)  # Construct full file path
  File "<frozen ntpath>", line 139, in join
  File "<frozen genericpath>", line 188, in _check_arg_types
TypeError: join() argument must be str, bytes, or os.PathLike object, not 'FieldFile'
"POST /print_order/ HTTP/1.1" 500 79654
Internal Server Error: /print/
Traceback (most recent call last):
  File "C:\Python313\Lib\site-packages\django\core\handlers\exception.py", line 55, in inner
    response = get_response(request)
  File "C:\Python313\Lib\site-packages\django\core\handlers\base.py", line 197, in _get_response
    response = wrapped_callback(request, *callback_args, **callback_kwargs)
  File "C:\Python313\Lib\site-packages\django\views\decorators\csrf.py", line 65, in _view_wrapper
    return view_func(request, *args, **kwargs)
  File "C:\Users\ratan\OneDrive\Desktop\PrintEase\SmartDocX\users\views.py", line 501, in print_document
    print('This is file path of printer function : ', file_path)
                                                      ^^^^
NameError: name 'file' is not defined
"POST /print/ HTTP/1.1" 500 72862
Internal Server Error: /print/
Traceback (most recent call last):
  File "C:\Python313\Lib\site-packages\django\core\handlers\exception.py", line 55, in inner
    response = get_response(request)
  File "C:\Python313\Lib\site-packages\django\core\handlers\base.py", line 197, in _get_response
    response = wrapped_callback(request, *callback_args, **callback_kwargs)
  File "C:\Python313\Lib\site-packages\django\views\decorators\csrf.py", line 65, in _view_wrapper
    return view_func(request, *args, **kwargs)
  File "C:\Users\ratan\OneDrive\Desktop\PrintEase\SmartDocX\users\views.py", line 501, in print_document
    print('This is file path of printer function : ', file_path)
                                                      ^^^^
NameError: name 'file' is not defined
"POST /print/ HTTP/1.1" 500 72862
Internal Server Error: /print/
Traceback (most recent call last):
  File "C:\Python313\Lib\site-packages\django\core\handlers\exception.py", line 55, in inner
    response = get_response(request)
  File "C:\Python313\Lib\site-packages\django\core\handlers\base.py", line 197, in _get_response
    response = wrapped_callback(request, *callback_args, **callback_kwargs)
  File "C:\Python313\Lib\site-packages\django\views\decorators\csrf.py", line 65, in _view_wrapper
    return view_func(request, *args, **kwargs)
  File "C:\Users\ratan\OneDrive\Desktop\PrintEase\SmartDocX\users\views.py", line 501, in print_document
    print('This is file path of printer function : ', file_path)
                                                      ^^^^
NameError: name 'file' is not defined
"POST /print/ HTTP/1.1" 500 72862
Internal Server Error: /print-document/
Traceback (most recent call last):
  File "C:\Python313\Lib\site-packages\django\core\handlers\exception.py", line 55, in inner
    response = get_response(request)
  File "C:\Python313\Lib\site-packages\django\core\handlers\base.py", line 197, in _get_response
    response = wrapped_callback(request, *callback_args, **callback_kwargs)
  File "C:\Users\ratan\OneDrive\Desktop\PrintEase\SmartDocX\users\views.py", line 539, in print_document
    file_path = request.POST("file_path")
TypeError: 'QueryDict' object is not callable
"POST /print-document/ HTTP/1.1" 500 68382
Internal Server Error: /print-document/
Traceback (most recent call last):
  File "C:\Python313\Lib\site-packages\django\core\handlers\exception.py", line 55, in inner
    response = get_response(request)
  File "C:\Python313\Lib\site-packages\django\core\handlers\base.py", line 197, in _get_response
    response = wrapped_callback(request, *callback_args, **callback_kwargs)
  File "C:\Users\ratan\OneDrive\Desktop\PrintEase\SmartDocX\users\views.py", line 539, in print_document
    file_path = request.POST("file_path")
TypeError: 'QueryDict' object is not callable
"POST /print-document/ HTTP/1.1" 500 68382
Internal Server Error: /upload/ratan-555b8a9d/
"POST /upload/ratan-555b8a9d/ HTTP/1.1" 500 144
Internal Server Error: /upload/ratan-555b8a9d/
"POST /upload/ratan-555b8a9d/ HTTP/1.1" 500 126
Internal Server Error: /pay/
Traceback (most recent call last):
  File "C:\Python313\Lib\site-packages\urllib3\connection.py", line 198, in _new_conn
    sock = connection.create_connection(
        (self._dns_host, self.port),
    ...<2 lines>...
        socket_options=self.socket_options,
    )
  File "C:\Python313\Lib\site-packages\urllib3\util\connection.py", line 60, in create_connection
    for res in socket.getaddrinfo(host, port, family, socket.SOCK_STREAM):
               ~~~~~~~~~~~~~~~~~~^^^^^^^^^^^^^^^^^^^^^^^^^^^^^^^^^^^^^^^^
  File "C:\Python313\Lib\socket.py", line 977, in getaddrinfo
    for res in _socket.getaddrinfo(host, port, family, type, proto, flags):
               ~~~~~~~~~~~~~~~~~~~^^^^^^^^^^^^^^^^^^^^^^^^^^^^^^^^^^^^^^^^
socket.gaierror: [Errno 11001] getaddrinfo failed

The above exception was the direct cause of the following exception:

Traceback (most recent call last):
  File "C:\Python313\Lib\site-packages\urllib3\connectionpool.py", line 787, in urlopen
    response = self._make_request(
        conn,
    ...<10 lines>...
        **response_kw,
    )
  File "C:\Python313\Lib\site-packages\urllib3\connectionpool.py", line 488, in _make_request
    raise new_e
  File "C:\Python313\Lib\site-packages\urllib3\connectionpool.py", line 464, in _make_request
    self._validate_conn(conn)
    ~~~~~~~~~~~~~~~~~~~^^^^^^
  File "C:\Python313\Lib\site-packages\urllib3\connectionpool.py", line 1093, in _validate_conn
    conn.connect()
    ~~~~~~~~~~~~^^
  File "C:\Python313\Lib\site-packages\urllib3\connection.py", line 704, in connect
    self.sock = sock = self._new_conn()
                       ~~~~~~~~~~~~~~^^
  File "C:\Python313\Lib\site-packages\urllib3\connection.py", line 205, in _new_conn
    raise NameResolutionError(self.host, self, e) from e
urllib3.exceptions.NameResolutionError: <urllib3.connection.HTTPSConnection object at 0x0000021F8C809FD0>: Failed to resolve 'api.razorpay.com' ([Errno 11001] getaddrinfo failed)

The above exception was the direct cause of the following exception:

Traceback (most recent call last):
  File "C:\Python313\Lib\site-packages\requests\adapters.py", line 667, in send
    resp = conn.urlopen(
        method=request.method,
    ...<9 lines>...
        chunked=chunked,
    )
  File "C:\Python313\Lib\site-packages\urllib3\connectionpool.py", line 841, in urlopen
    retries = retries.increment(
        method, url, error=new_e, _pool=self, _stacktrace=sys.exc_info()[2]
    )
  File "C:\Python313\Lib\site-packages\urllib3\util\retry.py", line 519, in increment
    raise MaxRetryError(_pool, url, reason) from reason  # type: ignore[arg-type]
    ^^^^^^^^^^^^^^^^^^^^^^^^^^^^^^^^^^^^^^^^^^^^^^^^^^^
urllib3.exceptions.MaxRetryError: HTTPSConnectionPool(host='api.razorpay.com', port=443): Max retries exceeded with url: /v1/orders (Caused by NameResolutionError("<urllib3.connection.HTTPSConnection object at 0x0000021F8C809FD0>: Failed to resolve 'api.razorpay.com' ([Errno 11001] getaddrinfo failed)"))

During handling of the above exception, another exception occurred:

Traceback (most recent call last):
  File "C:\Python313\Lib\site-packages\django\core\handlers\exception.py", line 55, in inner
    response = get_response(request)
  File "C:\Python313\Lib\site-packages\django\core\handlers\base.py", line 197, in _get_response
    response = wrapped_callback(request, *callback_args, **callback_kwargs)
  File "C:\Python313\Lib\site-packages\django\views\decorators\csrf.py", line 65, in _view_wrapper
    return view_func(request, *args, **kwargs)
  File "C:\Users\ratan\OneDrive\Desktop\PrintEase\SmartDocX\users\views.py", line 866, in create_payment
    payment_order = razorpay_client.order.create({
        "amount": amount,
        "currency": "INR",
        "payment_capture": 1
    })
  File "C:\Python313\Lib\site-packages\razorpay\resources\order.py", line 71, in create
    return self.post_url(url, data, **kwargs)
           ~~~~~~~~~~~~~^^^^^^^^^^^^^^^^^^^^^
  File "C:\Python313\Lib\site-packages\razorpay\resources\base.py", line 20, in post_url
    return self.client.post(url, data, **kwargs)
           ~~~~~~~~~~~~~~~~^^^^^^^^^^^^^^^^^^^^^
  File "C:\Python313\Lib\site-packages\razorpay\client.py", line 156, in post
    return self.request('post', path, data=data, **options)
           ~~~~~~~~~~~~^^^^^^^^^^^^^^^^^^^^^^^^^^^^^^^^^^^^
  File "C:\Python313\Lib\site-packages\razorpay\client.py", line 120, in request
    response = getattr(self.session, method)(url, auth=self.auth,
                                             verify=self.cert_path,
                                             **options)
  File "C:\Python313\Lib\site-packages\requests\sessions.py", line 637, in post
    return self.request("POST", url, data=data, json=json, **kwargs)
           ~~~~~~~~~~~~^^^^^^^^^^^^^^^^^^^^^^^^^^^^^^^^^^^^^^^^^^^^^
  File "C:\Python313\Lib\site-packages\requests\sessions.py", line 589, in request
    resp = self.send(prep, **send_kwargs)
  File "C:\Python313\Lib\site-packages\requests\sessions.py", line 703, in send
    r = adapter.send(request, **kwargs)
  File "C:\Python313\Lib\site-packages\requests\adapters.py", line 700, in send
    raise ConnectionError(e, request=request)
requests.exceptions.ConnectionError: HTTPSConnectionPool(host='api.razorpay.com', port=443): Max retries exceeded with url: /v1/orders (Caused by NameResolutionError("<urllib3.connection.HTTPSConnection object at 0x0000021F8C809FD0>: Failed to resolve 'api.razorpay.com' ([Errno 11001] getaddrinfo failed)"))
"POST /pay/ HTTP/1.1" 500 145
Internal Server Error: /pay/
Traceback (most recent call last):
  File "C:\Python313\Lib\site-packages\urllib3\connection.py", line 198, in _new_conn
    sock = connection.create_connection(
        (self._dns_host, self.port),
    ...<2 lines>...
        socket_options=self.socket_options,
    )
  File "C:\Python313\Lib\site-packages\urllib3\util\connection.py", line 60, in create_connection
    for res in socket.getaddrinfo(host, port, family, socket.SOCK_STREAM):
               ~~~~~~~~~~~~~~~~~~^^^^^^^^^^^^^^^^^^^^^^^^^^^^^^^^^^^^^^^^
  File "C:\Python313\Lib\socket.py", line 977, in getaddrinfo
    for res in _socket.getaddrinfo(host, port, family, type, proto, flags):
               ~~~~~~~~~~~~~~~~~~~^^^^^^^^^^^^^^^^^^^^^^^^^^^^^^^^^^^^^^^^
socket.gaierror: [Errno 11001] getaddrinfo failed

The above exception was the direct cause of the following exception:

Traceback (most recent call last):
  File "C:\Python313\Lib\site-packages\urllib3\connectionpool.py", line 787, in urlopen
    response = self._make_request(
        conn,
    ...<10 lines>...
        **response_kw,
    )
  File "C:\Python313\Lib\site-packages\urllib3\connectionpool.py", line 488, in _make_request
    raise new_e
  File "C:\Python313\Lib\site-packages\urllib3\connectionpool.py", line 464, in _make_request
    self._validate_conn(conn)
    ~~~~~~~~~~~~~~~~~~~^^^^^^
  File "C:\Python313\Lib\site-packages\urllib3\connectionpool.py", line 1093, in _validate_conn
    conn.connect()
    ~~~~~~~~~~~~^^
  File "C:\Python313\Lib\site-packages\urllib3\connection.py", line 704, in connect
    self.sock = sock = self._new_conn()
                       ~~~~~~~~~~~~~~^^
  File "C:\Python313\Lib\site-packages\urllib3\connection.py", line 205, in _new_conn
    raise NameResolutionError(self.host, self, e) from e
urllib3.exceptions.NameResolutionError: <urllib3.connection.HTTPSConnection object at 0x0000021F8CC46350>: Failed to resolve 'api.razorpay.com' ([Errno 11001] getaddrinfo failed)

The above exception was the direct cause of the following exception:

Traceback (most recent call last):
  File "C:\Python313\Lib\site-packages\requests\adapters.py", line 667, in send
    resp = conn.urlopen(
        method=request.method,
    ...<9 lines>...
        chunked=chunked,
    )
  File "C:\Python313\Lib\site-packages\urllib3\connectionpool.py", line 841, in urlopen
    retries = retries.increment(
        method, url, error=new_e, _pool=self, _stacktrace=sys.exc_info()[2]
    )
  File "C:\Python313\Lib\site-packages\urllib3\util\retry.py", line 519, in increment
    raise MaxRetryError(_pool, url, reason) from reason  # type: ignore[arg-type]
    ^^^^^^^^^^^^^^^^^^^^^^^^^^^^^^^^^^^^^^^^^^^^^^^^^^^
urllib3.exceptions.MaxRetryError: HTTPSConnectionPool(host='api.razorpay.com', port=443): Max retries exceeded with url: /v1/orders (Caused by NameResolutionError("<urllib3.connection.HTTPSConnection object at 0x0000021F8CC46350>: Failed to resolve 'api.razorpay.com' ([Errno 11001] getaddrinfo failed)"))

During handling of the above exception, another exception occurred:

Traceback (most recent call last):
  File "C:\Python313\Lib\site-packages\django\core\handlers\exception.py", line 55, in inner
    response = get_response(request)
  File "C:\Python313\Lib\site-packages\django\core\handlers\base.py", line 197, in _get_response
    response = wrapped_callback(request, *callback_args, **callback_kwargs)
  File "C:\Python313\Lib\site-packages\django\views\decorators\csrf.py", line 65, in _view_wrapper
    return view_func(request, *args, **kwargs)
  File "C:\Users\ratan\OneDrive\Desktop\PrintEase\SmartDocX\users\views.py", line 866, in create_payment
    payment_order = razorpay_client.order.create({
        "amount": amount,
        "currency": "INR",
        "payment_capture": 1
    })
  File "C:\Python313\Lib\site-packages\razorpay\resources\order.py", line 71, in create
    return self.post_url(url, data, **kwargs)
           ~~~~~~~~~~~~~^^^^^^^^^^^^^^^^^^^^^
  File "C:\Python313\Lib\site-packages\razorpay\resources\base.py", line 20, in post_url
    return self.client.post(url, data, **kwargs)
           ~~~~~~~~~~~~~~~~^^^^^^^^^^^^^^^^^^^^^
  File "C:\Python313\Lib\site-packages\razorpay\client.py", line 156, in post
    return self.request('post', path, data=data, **options)
           ~~~~~~~~~~~~^^^^^^^^^^^^^^^^^^^^^^^^^^^^^^^^^^^^
  File "C:\Python313\Lib\site-packages\razorpay\client.py", line 120, in request
    response = getattr(self.session, method)(url, auth=self.auth,
                                             verify=self.cert_path,
                                             **options)
  File "C:\Python313\Lib\site-packages\requests\sessions.py", line 637, in post
    return self.request("POST", url, data=data, json=json, **kwargs)
           ~~~~~~~~~~~~^^^^^^^^^^^^^^^^^^^^^^^^^^^^^^^^^^^^^^^^^^^^^
  File "C:\Python313\Lib\site-packages\requests\sessions.py", line 589, in request
    resp = self.send(prep, **send_kwargs)
  File "C:\Python313\Lib\site-packages\requests\sessions.py", line 703, in send
    r = adapter.send(request, **kwargs)
  File "C:\Python313\Lib\site-packages\requests\adapters.py", line 700, in send
    raise ConnectionError(e, request=request)
requests.exceptions.ConnectionError: HTTPSConnectionPool(host='api.razorpay.com', port=443): Max retries exceeded with url: /v1/orders (Caused by NameResolutionError("<urllib3.connection.HTTPSConnection object at 0x0000021F8CC46350>: Failed to resolve 'api.razorpay.com' ([Errno 11001] getaddrinfo failed)"))
"POST /pay/ HTTP/1.1" 500 145
Internal Server Error: /upload_document/
Traceback (most recent call last):
  File "C:\Users\ratan\OneDrive\Desktop\PrintEase\SmartDocX\myenv\Lib\site-packages\django\core\handlers\exception.py", line 55, in inner
    response = get_response(request)
  File "C:\Users\ratan\OneDrive\Desktop\PrintEase\SmartDocX\myenv\Lib\site-packages\django\core\handlers\base.py", line 197, in _get_response
    response = wrapped_callback(request, *callback_args, **callback_kwargs)
  File "C:\Users\ratan\OneDrive\Desktop\PrintEase\SmartDocX\myenv\Lib\site-packages\django\views\decorators\csrf.py", line 65, in _view_wrapper
    return view_func(request, *args, **kwargs)
TypeError: upload_document() missing 1 required positional argument: 'unique_url'
"GET /upload_document/ HTTP/1.1" 500 145
Internal Server Error: /upload_document/
Traceback (most recent call last):
  File "C:\Users\ratan\OneDrive\Desktop\PrintEase\SmartDocX\myenv\Lib\site-packages\django\core\handlers\exception.py", line 55, in inner
    response = get_response(request)
  File "C:\Users\ratan\OneDrive\Desktop\PrintEase\SmartDocX\myenv\Lib\site-packages\django\core\handlers\base.py", line 197, in _get_response
    response = wrapped_callback(request, *callback_args, **callback_kwargs)
  File "C:\Users\ratan\OneDrive\Desktop\PrintEase\SmartDocX\myenv\Lib\site-packages\django\views\decorators\csrf.py", line 65, in _view_wrapper
    return view_func(request, *args, **kwargs)
TypeError: upload_document() missing 1 required positional argument: 'unique_url'
"GET /upload_document/ HTTP/1.1" 500 145
Internal Server Error: /upload_document/
Traceback (most recent call last):
  File "C:\Users\ratan\OneDrive\Desktop\PrintEase\SmartDocX\myenv\Lib\site-packages\django\core\handlers\exception.py", line 55, in inner
    response = get_response(request)
  File "C:\Users\ratan\OneDrive\Desktop\PrintEase\SmartDocX\myenv\Lib\site-packages\django\core\handlers\base.py", line 197, in _get_response
    response = wrapped_callback(request, *callback_args, **callback_kwargs)
  File "C:\Users\ratan\OneDrive\Desktop\PrintEase\SmartDocX\myenv\Lib\site-packages\django\views\decorators\csrf.py", line 65, in _view_wrapper
    return view_func(request, *args, **kwargs)
TypeError: upload_document() missing 1 required positional argument: 'unique_url'
"GET /upload_document/ HTTP/1.1" 500 145
Internal Server Error: /upload_document/
Traceback (most recent call last):
  File "C:\Users\ratan\OneDrive\Desktop\PrintEase\SmartDocX\myenv\Lib\site-packages\django\core\handlers\exception.py", line 55, in inner
    response = get_response(request)
  File "C:\Users\ratan\OneDrive\Desktop\PrintEase\SmartDocX\myenv\Lib\site-packages\django\core\handlers\base.py", line 197, in _get_response
    response = wrapped_callback(request, *callback_args, **callback_kwargs)
  File "C:\Users\ratan\OneDrive\Desktop\PrintEase\SmartDocX\myenv\Lib\site-packages\django\views\decorators\csrf.py", line 65, in _view_wrapper
    return view_func(request, *args, **kwargs)
TypeError: upload_document() missing 1 required positional argument: 'unique_url'
"GET /upload_document/ HTTP/1.1" 500 145
Internal Server Error: /upload_document/
Traceback (most recent call last):
  File "C:\Users\ratan\OneDrive\Desktop\PrintEase\SmartDocX\myenv\Lib\site-packages\django\core\handlers\exception.py", line 55, in inner
    response = get_response(request)
  File "C:\Users\ratan\OneDrive\Desktop\PrintEase\SmartDocX\myenv\Lib\site-packages\django\core\handlers\base.py", line 197, in _get_response
    response = wrapped_callback(request, *callback_args, **callback_kwargs)
  File "C:\Users\ratan\OneDrive\Desktop\PrintEase\SmartDocX\myenv\Lib\site-packages\django\views\decorators\csrf.py", line 65, in _view_wrapper
    return view_func(request, *args, **kwargs)
TypeError: upload_document() missing 1 required positional argument: 'unique_url'
"GET /upload_document/ HTTP/1.1" 500 145
Internal Server Error: /upload_document/
Traceback (most recent call last):
  File "C:\Users\ratan\OneDrive\Desktop\PrintEase\SmartDocX\myenv\Lib\site-packages\django\core\handlers\exception.py", line 55, in inner
    response = get_response(request)
  File "C:\Users\ratan\OneDrive\Desktop\PrintEase\SmartDocX\myenv\Lib\site-packages\django\core\handlers\base.py", line 197, in _get_response
    response = wrapped_callback(request, *callback_args, **callback_kwargs)
  File "C:\Users\ratan\OneDrive\Desktop\PrintEase\SmartDocX\myenv\Lib\site-packages\django\views\decorators\csrf.py", line 65, in _view_wrapper
    return view_func(request, *args, **kwargs)
TypeError: upload_document() missing 1 required positional argument: 'unique_url'
"GET /upload_document/ HTTP/1.1" 500 145
Internal Server Error: /dashboard/
Traceback (most recent call last):
  File "C:\Users\ratan\OneDrive\Desktop\PrintEase\SmartDocX\myenv\Lib\site-packages\django\core\handlers\exception.py", line 55, in inner
    response = get_response(request)
  File "C:\Users\ratan\OneDrive\Desktop\PrintEase\SmartDocX\myenv\Lib\site-packages\django\core\handlers\base.py", line 197, in _get_response
    response = wrapped_callback(request, *callback_args, **callback_kwargs)
  File "C:\Users\ratan\OneDrive\Desktop\PrintEase\SmartDocX\myenv\Lib\site-packages\django\contrib\auth\decorators.py", line 60, in _view_wrapper
    return view_func(request, *args, **kwargs)
  File "C:\Users\ratan\OneDrive\Desktop\PrintEase\SmartDocX\users\views.py", line 452, in dashboard
    return render(request, "users/dashboard.html", {
        "user": user,
    ...<7 lines>...
        "order_table": order_table
    })
  File "C:\Users\ratan\OneDrive\Desktop\PrintEase\SmartDocX\myenv\Lib\site-packages\django\shortcuts.py", line 25, in render
    content = loader.render_to_string(template_name, context, request, using=using)
  File "C:\Users\ratan\OneDrive\Desktop\PrintEase\SmartDocX\myenv\Lib\site-packages\django\template\loader.py", line 62, in render_to_string
    return template.render(context, request)
           ~~~~~~~~~~~~~~~^^^^^^^^^^^^^^^^^^
  File "C:\Users\ratan\OneDrive\Desktop\PrintEase\SmartDocX\myenv\Lib\site-packages\django\template\backends\django.py", line 107, in render
    return self.template.render(context)
           ~~~~~~~~~~~~~~~~~~~~^^^^^^^^^
  File "C:\Users\ratan\OneDrive\Desktop\PrintEase\SmartDocX\myenv\Lib\site-packages\django\template\base.py", line 171, in render
    return self._render(context)
           ~~~~~~~~~~~~^^^^^^^^^
  File "C:\Users\ratan\OneDrive\Desktop\PrintEase\SmartDocX\myenv\Lib\site-packages\django\template\base.py", line 163, in _render
    return self.nodelist.render(context)
           ~~~~~~~~~~~~~~~~~~~~^^^^^^^^^
  File "C:\Users\ratan\OneDrive\Desktop\PrintEase\SmartDocX\myenv\Lib\site-packages\django\template\base.py", line 1008, in render
    return SafeString("".join([node.render_annotated(context) for node in self]))
                               ~~~~~~~~~~~~~~~~~~~~~^^^^^^^^^
  File "C:\Users\ratan\OneDrive\Desktop\PrintEase\SmartDocX\myenv\Lib\site-packages\django\template\base.py", line 969, in render_annotated
    return self.render(context)
           ~~~~~~~~~~~^^^^^^^^^
  File "C:\Users\ratan\OneDrive\Desktop\PrintEase\SmartDocX\myenv\Lib\site-packages\django\template\defaulttags.py", line 243, in render
    nodelist.append(node.render_annotated(context))
                    ~~~~~~~~~~~~~~~~~~~~~^^^^^^^^^
  File "C:\Users\ratan\OneDrive\Desktop\PrintEase\SmartDocX\myenv\Lib\site-packages\django\template\base.py", line 969, in render_annotated
    return self.render(context)
           ~~~~~~~~~~~^^^^^^^^^
  File "C:\Users\ratan\OneDrive\Desktop\PrintEase\SmartDocX\myenv\Lib\site-packages\django\template\defaulttags.py", line 480, in render
    url = reverse(view_name, args=args, kwargs=kwargs, current_app=current_app)
  File "C:\Users\ratan\OneDrive\Desktop\PrintEase\SmartDocX\myenv\Lib\site-packages\django\urls\base.py", line 88, in reverse
    return resolver._reverse_with_prefix(view, prefix, *args, **kwargs)
           ~~~~~~~~~~~~~~~~~~~~~~~~~~~~~^^^^^^^^^^^^^^^^^^^^^^^^^^^^^^^
  File "C:\Users\ratan\OneDrive\Desktop\PrintEase\SmartDocX\myenv\Lib\site-packages\django\urls\resolvers.py", line 831, in _reverse_with_prefix
    raise NoReverseMatch(msg)
django.urls.exceptions.NoReverseMatch: Reverse for 'serve_file' not found. 'serve_file' is not a valid view function or pattern name.
"GET /dashboard/ HTTP/1.1" 500 145
Internal Server Error: /dashboard/
Traceback (most recent call last):
  File "C:\Users\ratan\OneDrive\Desktop\PrintEase\SmartDocX\myenv\Lib\site-packages\django\core\handlers\exception.py", line 55, in inner
    response = get_response(request)
  File "C:\Users\ratan\OneDrive\Desktop\PrintEase\SmartDocX\myenv\Lib\site-packages\django\core\handlers\base.py", line 197, in _get_response
    response = wrapped_callback(request, *callback_args, **callback_kwargs)
  File "C:\Users\ratan\OneDrive\Desktop\PrintEase\SmartDocX\myenv\Lib\site-packages\django\contrib\auth\decorators.py", line 60, in _view_wrapper
    return view_func(request, *args, **kwargs)
  File "C:\Users\ratan\OneDrive\Desktop\PrintEase\SmartDocX\users\views.py", line 452, in dashboard
    return render(request, "users/dashboard.html", {
        "user": user,
    ...<7 lines>...
        "order_table": order_table
    })
  File "C:\Users\ratan\OneDrive\Desktop\PrintEase\SmartDocX\myenv\Lib\site-packages\django\shortcuts.py", line 25, in render
    content = loader.render_to_string(template_name, context, request, using=using)
  File "C:\Users\ratan\OneDrive\Desktop\PrintEase\SmartDocX\myenv\Lib\site-packages\django\template\loader.py", line 62, in render_to_string
    return template.render(context, request)
           ~~~~~~~~~~~~~~~^^^^^^^^^^^^^^^^^^
  File "C:\Users\ratan\OneDrive\Desktop\PrintEase\SmartDocX\myenv\Lib\site-packages\django\template\backends\django.py", line 107, in render
    return self.template.render(context)
           ~~~~~~~~~~~~~~~~~~~~^^^^^^^^^
  File "C:\Users\ratan\OneDrive\Desktop\PrintEase\SmartDocX\myenv\Lib\site-packages\django\template\base.py", line 171, in render
    return self._render(context)
           ~~~~~~~~~~~~^^^^^^^^^
  File "C:\Users\ratan\OneDrive\Desktop\PrintEase\SmartDocX\myenv\Lib\site-packages\django\template\base.py", line 163, in _render
    return self.nodelist.render(context)
           ~~~~~~~~~~~~~~~~~~~~^^^^^^^^^
  File "C:\Users\ratan\OneDrive\Desktop\PrintEase\SmartDocX\myenv\Lib\site-packages\django\template\base.py", line 1008, in render
    return SafeString("".join([node.render_annotated(context) for node in self]))
                               ~~~~~~~~~~~~~~~~~~~~~^^^^^^^^^
  File "C:\Users\ratan\OneDrive\Desktop\PrintEase\SmartDocX\myenv\Lib\site-packages\django\template\base.py", line 969, in render_annotated
    return self.render(context)
           ~~~~~~~~~~~^^^^^^^^^
  File "C:\Users\ratan\OneDrive\Desktop\PrintEase\SmartDocX\myenv\Lib\site-packages\django\template\defaulttags.py", line 243, in render
    nodelist.append(node.render_annotated(context))
                    ~~~~~~~~~~~~~~~~~~~~~^^^^^^^^^
  File "C:\Users\ratan\OneDrive\Desktop\PrintEase\SmartDocX\myenv\Lib\site-packages\django\template\base.py", line 969, in render_annotated
    return self.render(context)
           ~~~~~~~~~~~^^^^^^^^^
  File "C:\Users\ratan\OneDrive\Desktop\PrintEase\SmartDocX\myenv\Lib\site-packages\django\template\defaulttags.py", line 480, in render
    url = reverse(view_name, args=args, kwargs=kwargs, current_app=current_app)
  File "C:\Users\ratan\OneDrive\Desktop\PrintEase\SmartDocX\myenv\Lib\site-packages\django\urls\base.py", line 88, in reverse
    return resolver._reverse_with_prefix(view, prefix, *args, **kwargs)
           ~~~~~~~~~~~~~~~~~~~~~~~~~~~~~^^^^^^^^^^^^^^^^^^^^^^^^^^^^^^^
  File "C:\Users\ratan\OneDrive\Desktop\PrintEase\SmartDocX\myenv\Lib\site-packages\django\urls\resolvers.py", line 831, in _reverse_with_prefix
    raise NoReverseMatch(msg)
django.urls.exceptions.NoReverseMatch: Reverse for 'serve_file' not found. 'serve_file' is not a valid view function or pattern name.
"GET /dashboard/ HTTP/1.1" 500 145
Internal Server Error: /exitstingshops/
Traceback (most recent call last):
  File "C:\Users\ratan\OneDrive\Desktop\PrintEase\SmartDocX\myenv\Lib\site-packages\django\core\handlers\exception.py", line 55, in inner
    response = get_response(request)
  File "C:\Users\ratan\OneDrive\Desktop\PrintEase\SmartDocX\myenv\Lib\site-packages\django\core\handlers\base.py", line 197, in _get_response
    response = wrapped_callback(request, *callback_args, **callback_kwargs)
TypeError: exitstingshops() takes 0 positional arguments but 1 was given
"GET /exitstingshops/ HTTP/1.1" 500 65458
Internal Server Error: /exitstingshops/
Traceback (most recent call last):
  File "C:\Users\ratan\OneDrive\Desktop\PrintEase\SmartDocX\myenv\Lib\site-packages\django\core\handlers\exception.py", line 55, in inner
    response = get_response(request)
  File "C:\Users\ratan\OneDrive\Desktop\PrintEase\SmartDocX\myenv\Lib\site-packages\django\core\handlers\base.py", line 197, in _get_response
    response = wrapped_callback(request, *callback_args, **callback_kwargs)
  File "C:\Users\ratan\OneDrive\Desktop\PrintEase\SmartDocX\users\views.py", line 877, in exitstingshops
    return render('users/existingshops.html')
TypeError: render() missing 1 required positional argument: 'template_name'
"GET /exitstingshops/ HTTP/1.1" 500 68974
Internal Server Error: /registered_shops/
Traceback (most recent call last):
  File "C:\Users\ratan\OneDrive\Desktop\PrintEase\SmartDocX\myenv\Lib\site-packages\django\core\handlers\exception.py", line 55, in inner
    response = get_response(request)
  File "C:\Users\ratan\OneDrive\Desktop\PrintEase\SmartDocX\myenv\Lib\site-packages\django\core\handlers\base.py", line 197, in _get_response
    response = wrapped_callback(request, *callback_args, **callback_kwargs)
  File "C:\Users\ratan\OneDrive\Desktop\PrintEase\SmartDocX\users\views.py", line 889, in exitstingshops
    return render(request, 'registered_shops.html', {'shops': shop_data})
  File "C:\Users\ratan\OneDrive\Desktop\PrintEase\SmartDocX\myenv\Lib\site-packages\django\shortcuts.py", line 25, in render
    content = loader.render_to_string(template_name, context, request, using=using)
  File "C:\Users\ratan\OneDrive\Desktop\PrintEase\SmartDocX\myenv\Lib\site-packages\django\template\loader.py", line 61, in render_to_string
    template = get_template(template_name, using=using)
  File "C:\Users\ratan\OneDrive\Desktop\PrintEase\SmartDocX\myenv\Lib\site-packages\django\template\loader.py", line 19, in get_template
    raise TemplateDoesNotExist(template_name, chain=chain)
django.template.exceptions.TemplateDoesNotExist: registered_shops.html
"GET /registered_shops/ HTTP/1.1" 500 86785
Internal Server Error: /exitstingshops/
Traceback (most recent call last):
  File "C:\Users\ratan\OneDrive\Desktop\PrintEase\SmartDocX\myenv\Lib\site-packages\django\core\handlers\exception.py", line 55, in inner
    response = get_response(request)
  File "C:\Users\ratan\OneDrive\Desktop\PrintEase\SmartDocX\myenv\Lib\site-packages\django\core\handlers\base.py", line 197, in _get_response
    response = wrapped_callback(request, *callback_args, **callback_kwargs)
  File "C:\Users\ratan\OneDrive\Desktop\PrintEase\SmartDocX\users\views.py", line 889, in exitstingshops
    return render(request, 'exitstingshops.html', {'shops': shop_data})
  File "C:\Users\ratan\OneDrive\Desktop\PrintEase\SmartDocX\myenv\Lib\site-packages\django\shortcuts.py", line 25, in render
    content = loader.render_to_string(template_name, context, request, using=using)
  File "C:\Users\ratan\OneDrive\Desktop\PrintEase\SmartDocX\myenv\Lib\site-packages\django\template\loader.py", line 61, in render_to_string
    template = get_template(template_name, using=using)
  File "C:\Users\ratan\OneDrive\Desktop\PrintEase\SmartDocX\myenv\Lib\site-packages\django\template\loader.py", line 19, in get_template
    raise TemplateDoesNotExist(template_name, chain=chain)
django.template.exceptions.TemplateDoesNotExist: exitstingshops.html
"GET /exitstingshops/ HTTP/1.1" 500 86725
Internal Server Error: /exitstingshops/
Traceback (most recent call last):
  File "C:\Users\ratan\OneDrive\Desktop\PrintEase\SmartDocX\myenv\Lib\site-packages\django\core\handlers\exception.py", line 55, in inner
    response = get_response(request)
  File "C:\Users\ratan\OneDrive\Desktop\PrintEase\SmartDocX\myenv\Lib\site-packages\django\core\handlers\base.py", line 197, in _get_response
    response = wrapped_callback(request, *callback_args, **callback_kwargs)
  File "C:\Users\ratan\OneDrive\Desktop\PrintEase\SmartDocX\users\views.py", line 889, in exitstingshops
    return render(request, 'exitstingshops.html', {'shops': shop_data})
  File "C:\Users\ratan\OneDrive\Desktop\PrintEase\SmartDocX\myenv\Lib\site-packages\django\shortcuts.py", line 25, in render
    content = loader.render_to_string(template_name, context, request, using=using)
  File "C:\Users\ratan\OneDrive\Desktop\PrintEase\SmartDocX\myenv\Lib\site-packages\django\template\loader.py", line 61, in render_to_string
    template = get_template(template_name, using=using)
  File "C:\Users\ratan\OneDrive\Desktop\PrintEase\SmartDocX\myenv\Lib\site-packages\django\template\loader.py", line 19, in get_template
    raise TemplateDoesNotExist(template_name, chain=chain)
django.template.exceptions.TemplateDoesNotExist: exitstingshops.html
"GET /exitstingshops/ HTTP/1.1" 500 86725
Internal Server Error: /exitstingshops/
Traceback (most recent call last):
  File "C:\Users\ratan\OneDrive\Desktop\PrintEase\SmartDocX\myenv\Lib\site-packages\django\core\handlers\exception.py", line 55, in inner
    response = get_response(request)
  File "C:\Users\ratan\OneDrive\Desktop\PrintEase\SmartDocX\myenv\Lib\site-packages\django\core\handlers\base.py", line 197, in _get_response
    response = wrapped_callback(request, *callback_args, **callback_kwargs)
  File "C:\Users\ratan\OneDrive\Desktop\PrintEase\SmartDocX\users\views.py", line 889, in exitstingshops
    return render(request, 'exitstingshops.html', {'shops': shop_data})
  File "C:\Users\ratan\OneDrive\Desktop\PrintEase\SmartDocX\myenv\Lib\site-packages\django\shortcuts.py", line 25, in render
    content = loader.render_to_string(template_name, context, request, using=using)
  File "C:\Users\ratan\OneDrive\Desktop\PrintEase\SmartDocX\myenv\Lib\site-packages\django\template\loader.py", line 61, in render_to_string
    template = get_template(template_name, using=using)
  File "C:\Users\ratan\OneDrive\Desktop\PrintEase\SmartDocX\myenv\Lib\site-packages\django\template\loader.py", line 19, in get_template
    raise TemplateDoesNotExist(template_name, chain=chain)
django.template.exceptions.TemplateDoesNotExist: exitstingshops.html
"GET /exitstingshops/ HTTP/1.1" 500 86725
Internal Server Error: /upload/ratan-ef18ed52/
Traceback (most recent call last):
  File "C:\Users\ratan\OneDrive\Desktop\PrintEase\SmartDocX\myenv\Lib\site-packages\django\template\base.py", line 510, in parse
    compile_func = self.tags[command]
                   ~~~~~~~~~^^^^^^^^^
KeyError: 'endblock'

During handling of the above exception, another exception occurred:

Traceback (most recent call last):
  File "C:\Users\ratan\OneDrive\Desktop\PrintEase\SmartDocX\myenv\Lib\site-packages\django\core\handlers\exception.py", line 55, in inner
    response = get_response(request)
  File "C:\Users\ratan\OneDrive\Desktop\PrintEase\SmartDocX\myenv\Lib\site-packages\django\core\handlers\base.py", line 197, in _get_response
    response = wrapped_callback(request, *callback_args, **callback_kwargs)
  File "C:\Users\ratan\OneDrive\Desktop\PrintEase\SmartDocX\myenv\Lib\site-packages\django\views\decorators\csrf.py", line 65, in _view_wrapper
    return view_func(request, *args, **kwargs)
  File "C:\Users\ratan\OneDrive\Desktop\PrintEase\SmartDocX\users\views.py", line 763, in upload_document
    return render(request, 'customer/upload_document.html', {'user': user, 'unique_url': unique_url, "key": settings.RAZORPAY_KEY_ID})
  File "C:\Users\ratan\OneDrive\Desktop\PrintEase\SmartDocX\myenv\Lib\site-packages\django\shortcuts.py", line 25, in render
    content = loader.render_to_string(template_name, context, request, using=using)
  File "C:\Users\ratan\OneDrive\Desktop\PrintEase\SmartDocX\myenv\Lib\site-packages\django\template\loader.py", line 61, in render_to_string
    template = get_template(template_name, using=using)
  File "C:\Users\ratan\OneDrive\Desktop\PrintEase\SmartDocX\myenv\Lib\site-packages\django\template\loader.py", line 15, in get_template
    return engine.get_template(template_name)
           ~~~~~~~~~~~~~~~~~~~^^^^^^^^^^^^^^^
  File "C:\Users\ratan\OneDrive\Desktop\PrintEase\SmartDocX\myenv\Lib\site-packages\django\template\backends\django.py", line 79, in get_template
    return Template(self.engine.get_template(template_name), self)
                    ~~~~~~~~~~~~~~~~~~~~~~~~^^^^^^^^^^^^^^^
  File "C:\Users\ratan\OneDrive\Desktop\PrintEase\SmartDocX\myenv\Lib\site-packages\django\template\engine.py", line 177, in get_template
    template, origin = self.find_template(template_name)
                       ~~~~~~~~~~~~~~~~~~^^^^^^^^^^^^^^^
  File "C:\Users\ratan\OneDrive\Desktop\PrintEase\SmartDocX\myenv\Lib\site-packages\django\template\engine.py", line 159, in find_template
    template = loader.get_template(name, skip=skip)
  File "C:\Users\ratan\OneDrive\Desktop\PrintEase\SmartDocX\myenv\Lib\site-packages\django\template\loaders\cached.py", line 57, in get_template
    template = super().get_template(template_name, skip)
  File "C:\Users\ratan\OneDrive\Desktop\PrintEase\SmartDocX\myenv\Lib\site-packages\django\template\loaders\base.py", line 28, in get_template
    return Template(
        contents,
    ...<2 lines>...
        self.engine,
    )
  File "C:\Users\ratan\OneDrive\Desktop\PrintEase\SmartDocX\myenv\Lib\site-packages\django\template\base.py", line 154, in __init__
    self.nodelist = self.compile_nodelist()
                    ~~~~~~~~~~~~~~~~~~~~~^^
  File "C:\Users\ratan\OneDrive\Desktop\PrintEase\SmartDocX\myenv\Lib\site-packages\django\template\base.py", line 196, in compile_nodelist
    nodelist = parser.parse()
  File "C:\Users\ratan\OneDrive\Desktop\PrintEase\SmartDocX\myenv\Lib\site-packages\django\template\base.py", line 512, in parse
    self.invalid_block_tag(token, command, parse_until)
    ~~~~~~~~~~~~~~~~~~~~~~^^^^^^^^^^^^^^^^^^^^^^^^^^^^^
  File "C:\Users\ratan\OneDrive\Desktop\PrintEase\SmartDocX\myenv\Lib\site-packages\django\template\base.py", line 573, in invalid_block_tag
    raise self.error(
    ...<3 lines>...
    )
django.template.exceptions.TemplateSyntaxError: Invalid block tag on line 877: 'endblock'. Did you forget to register or load this tag?
"GET /upload/ratan-ef18ed52/ HTTP/1.1" 500 160417
Internal Server Error: /upload/ratan-ef18ed52/
Traceback (most recent call last):
  File "C:\Users\ratan\OneDrive\Desktop\PrintEase\SmartDocX\myenv\Lib\site-packages\django\template\base.py", line 510, in parse
    compile_func = self.tags[command]
                   ~~~~~~~~~^^^^^^^^^
KeyError: 'endblock'

During handling of the above exception, another exception occurred:

Traceback (most recent call last):
  File "C:\Users\ratan\OneDrive\Desktop\PrintEase\SmartDocX\myenv\Lib\site-packages\django\core\handlers\exception.py", line 55, in inner
    response = get_response(request)
  File "C:\Users\ratan\OneDrive\Desktop\PrintEase\SmartDocX\myenv\Lib\site-packages\django\core\handlers\base.py", line 197, in _get_response
    response = wrapped_callback(request, *callback_args, **callback_kwargs)
  File "C:\Users\ratan\OneDrive\Desktop\PrintEase\SmartDocX\myenv\Lib\site-packages\django\views\decorators\csrf.py", line 65, in _view_wrapper
    return view_func(request, *args, **kwargs)
  File "C:\Users\ratan\OneDrive\Desktop\PrintEase\SmartDocX\users\views.py", line 763, in upload_document
    return render(request, 'customer/upload_document.html', {'user': user, 'unique_url': unique_url, "key": settings.RAZORPAY_KEY_ID})
  File "C:\Users\ratan\OneDrive\Desktop\PrintEase\SmartDocX\myenv\Lib\site-packages\django\shortcuts.py", line 25, in render
    content = loader.render_to_string(template_name, context, request, using=using)
  File "C:\Users\ratan\OneDrive\Desktop\PrintEase\SmartDocX\myenv\Lib\site-packages\django\template\loader.py", line 61, in render_to_string
    template = get_template(template_name, using=using)
  File "C:\Users\ratan\OneDrive\Desktop\PrintEase\SmartDocX\myenv\Lib\site-packages\django\template\loader.py", line 15, in get_template
    return engine.get_template(template_name)
           ~~~~~~~~~~~~~~~~~~~^^^^^^^^^^^^^^^
  File "C:\Users\ratan\OneDrive\Desktop\PrintEase\SmartDocX\myenv\Lib\site-packages\django\template\backends\django.py", line 79, in get_template
    return Template(self.engine.get_template(template_name), self)
                    ~~~~~~~~~~~~~~~~~~~~~~~~^^^^^^^^^^^^^^^
  File "C:\Users\ratan\OneDrive\Desktop\PrintEase\SmartDocX\myenv\Lib\site-packages\django\template\engine.py", line 177, in get_template
    template, origin = self.find_template(template_name)
                       ~~~~~~~~~~~~~~~~~~^^^^^^^^^^^^^^^
  File "C:\Users\ratan\OneDrive\Desktop\PrintEase\SmartDocX\myenv\Lib\site-packages\django\template\engine.py", line 159, in find_template
    template = loader.get_template(name, skip=skip)
  File "C:\Users\ratan\OneDrive\Desktop\PrintEase\SmartDocX\myenv\Lib\site-packages\django\template\loaders\cached.py", line 57, in get_template
    template = super().get_template(template_name, skip)
  File "C:\Users\ratan\OneDrive\Desktop\PrintEase\SmartDocX\myenv\Lib\site-packages\django\template\loaders\base.py", line 28, in get_template
    return Template(
        contents,
    ...<2 lines>...
        self.engine,
    )
  File "C:\Users\ratan\OneDrive\Desktop\PrintEase\SmartDocX\myenv\Lib\site-packages\django\template\base.py", line 154, in __init__
    self.nodelist = self.compile_nodelist()
                    ~~~~~~~~~~~~~~~~~~~~~^^
  File "C:\Users\ratan\OneDrive\Desktop\PrintEase\SmartDocX\myenv\Lib\site-packages\django\template\base.py", line 196, in compile_nodelist
    nodelist = parser.parse()
  File "C:\Users\ratan\OneDrive\Desktop\PrintEase\SmartDocX\myenv\Lib\site-packages\django\template\base.py", line 512, in parse
    self.invalid_block_tag(token, command, parse_until)
    ~~~~~~~~~~~~~~~~~~~~~~^^^^^^^^^^^^^^^^^^^^^^^^^^^^^
  File "C:\Users\ratan\OneDrive\Desktop\PrintEase\SmartDocX\myenv\Lib\site-packages\django\template\base.py", line 573, in invalid_block_tag
    raise self.error(
    ...<3 lines>...
    )
django.template.exceptions.TemplateSyntaxError: Invalid block tag on line 877: 'endblock'. Did you forget to register or load this tag?
"GET /upload/ratan-ef18ed52/ HTTP/1.1" 500 160256
Internal Server Error: /print-document/
"POST /print-document/ HTTP/1.1" 500 44
Internal Server Error: /print-document/
"POST /print-document/ HTTP/1.1" 500 44
Internal Server Error: /print-document/
"POST /print-document/ HTTP/1.1" 500 44
Internal Server Error: /print-document/
"POST /print-document/ HTTP/1.1" 500 44
Internal Server Error: /print-document/
"POST /print-document/ HTTP/1.1" 500 41
Internal Server Error: /print-document/
"POST /print-document/ HTTP/1.1" 500 60
Internal Server Error: /print-document/
"POST /print-document/ HTTP/1.1" 500 78
Internal Server Error: /print-document/
Traceback (most recent call last):
  File "C:\Users\ratan\OneDrive\Desktop\PrintEase\SmartDocX\myenv\Lib\site-packages\django\core\handlers\exception.py", line 55, in inner
    response = get_response(request)
  File "C:\Users\ratan\OneDrive\Desktop\PrintEase\SmartDocX\myenv\Lib\site-packages\django\core\handlers\base.py", line 197, in _get_response
    response = wrapped_callback(request, *callback_args, **callback_kwargs)
  File "C:\Users\ratan\OneDrive\Desktop\PrintEase\SmartDocX\users\views.py", line 625, in print_document
    file_path = file_path.replace("bananas", "apples")
                ^^^^^^^^^
NameError: name 'file_patk' is not defined. Did you mean: 'file_path'?
"POST /print-document/ HTTP/1.1" 500 72271
Internal Server Error: /print-document/
"POST /print-document/ HTTP/1.1" 500 67
Internal Server Error: /print-document/
"POST /print-document/ HTTP/1.1" 500 67
Internal Server Error: /print-document/
"POST /print-document/ HTTP/1.1" 500 67
Internal Server Error: /print-document/
"POST /print-document/ HTTP/1.1" 500 67
Internal Server Error: /print-document/
"POST /print-document/ HTTP/1.1" 500 67
Internal Server Error: /print-document/
"POST /print-document/ HTTP/1.1" 500 67
Internal Server Error: /print-document/
"POST /print-document/ HTTP/1.1" 500 67
Internal Server Error: /print-document/
"POST /print-document/ HTTP/1.1" 500 67
Internal Server Error: /print-document/
"POST /print-document/ HTTP/1.1" 500 67
Internal Server Error: /print-document/
"POST /print-document/ HTTP/1.1" 500 67
Internal Server Error: /print-document/
"POST /print-document/ HTTP/1.1" 500 67
Internal Server Error: /print-document/
"POST /print-document/ HTTP/1.1" 500 67
Internal Server Error: /print-document/
"POST /print-document/ HTTP/1.1" 500 67
Internal Server Error: /print-document/
"POST /print-document/ HTTP/1.1" 500 67
Internal Server Error: /print-document/
"POST /print-document/ HTTP/1.1" 500 67
Internal Server Error: /print-document/
"POST /print-document/ HTTP/1.1" 500 67
Internal Server Error: /print-document/
"POST /print-document/ HTTP/1.1" 500 67
Internal Server Error: /print-document/
"POST /print-document/ HTTP/1.1" 500 67
Internal Server Error: /print-document/
"POST /print-document/ HTTP/1.1" 500 67
Internal Server Error: /print-document/
"POST /print-document/ HTTP/1.1" 500 67
Internal Server Error: /print-document/
"POST /print-document/ HTTP/1.1" 500 67
Internal Server Error: /print-document/
"POST /print-document/ HTTP/1.1" 500 96
Internal Server Error: /print-document/
"POST /print-document/ HTTP/1.1" 500 67
Internal Server Error: /print-document/
"POST /print-document/ HTTP/1.1" 500 67
Internal Server Error: /print-document/
"POST /print-document/ HTTP/1.1" 500 67
Internal Server Error: /print-document/
"POST /print-document/ HTTP/1.1" 500 67
Internal Server Error: /print-document/
"POST /print-document/ HTTP/1.1" 500 67
Internal Server Error: /print-document/
"POST /print-document/ HTTP/1.1" 500 67
Internal Server Error: /print-document/
"POST /print-document/ HTTP/1.1" 500 67
Internal Server Error: /print-document/
"POST /print-document/ HTTP/1.1" 500 67
Internal Server Error: /print-document/
"POST /print-document/ HTTP/1.1" 500 67
Internal Server Error: /print-document/
"POST /print-document/ HTTP/1.1" 500 67
Internal Server Error: /print-document/
"POST /print-document/ HTTP/1.1" 500 67
Internal Server Error: /print-document/
"POST /print-document/ HTTP/1.1" 500 67
Internal Server Error: /print-document/
"POST /print-document/ HTTP/1.1" 500 83
Internal Server Error: /print-document/
"POST /print-document/ HTTP/1.1" 500 83
Internal Server Error: /print-document/
"POST /print-document/ HTTP/1.1" 500 86
Internal Server Error: /print-document/
"POST /print-document/ HTTP/1.1" 500 86
Internal Server Error: /print-document/
"POST /print-document/ HTTP/1.1" 500 86
